<?xml version="1.0" ?>
<robot name="day" xmlns:xacro="http://www.ros.org/wiki/xacro">

<xacro:include filename="$(find day_description)/urdf/materials.xacro" />
<xacro:include filename="$(find day_description)/urdf/day.trans" />
<xacro:include filename="$(find day_description)/urdf/day.gazebo" />
<link name="base_link">
  <inertial>
    <origin xyz="0.20755223500193812 0.08874499095207393 -0.28694965036870895" rpy="0 0 0"/>
    <mass value="2.8894718370283434"/>
    <inertia ixx="0.002711" iyy="0.010219" izz="0.012321" ixy="-3.5e-05" iyz="-1e-05" ixz="-0.000456"/>
  </inertial>
  <visual>
    <origin xyz="0 0 0" rpy="0 0 0"/>
    <geometry>
      <mesh filename="package://day_description/meshes/base_link.stl" scale="0.001 0.001 0.001"/>
    </geometry>
    <material name="silver"/>
  </visual>
  <collision>
    <origin xyz="0 0 0" rpy="0 0 0"/>
    <geometry>
      <mesh filename="package://day_description/meshes/base_link.stl" scale="0.001 0.001 0.001"/>
    </geometry>
  </collision>
</link>

<link name="left_wheel_1">
  <inertial>
    <origin xyz="-2.5833728548030344e-07 0.0025002210465544794 -3.53264753505389e-07" rpy="0 0 0"/>
    <mass value="0.1109767604880594"/>
    <inertia ixx="2.5e-05" iyy="5e-05" izz="2.5e-05" ixy="-0.0" iyz="-0.0" ixz="-0.0"/>
  </inertial>
  <visual>
    <origin xyz="-0.126106 -0.143452 0.307951" rpy="0 0 0"/>
    <geometry>
      <mesh filename="package://day_description/meshes/left_wheel_1.stl" scale="0.001 0.001 0.001"/>
    </geometry>
    <material name="silver"/>
  </visual>
  <collision>
    <origin xyz="-0.126106 -0.143452 0.307951" rpy="0 0 0"/>
    <geometry>
      <mesh filename="package://day_description/meshes/left_wheel_1.stl" scale="0.001 0.001 0.001"/>
    </geometry>
  </collision>
</link>

<link name="right_wheel_1">
  <inertial>
    <origin xyz="-5.190943597188635e-08 -0.002499778953445317 3.485909061407e-07" rpy="0 0 0"/>
    <mass value="0.11097676048805943"/>
    <inertia ixx="2.5e-05" iyy="5e-05" izz="2.5e-05" ixy="-0.0" iyz="-0.0" ixz="-0.0"/>
  </inertial>
  <visual>
    <origin xyz="-0.129269 -0.033452 0.3081" rpy="0 0 0"/>
    <geometry>
      <mesh filename="package://day_description/meshes/right_wheel_1.stl" scale="0.001 0.001 0.001"/>
    </geometry>
    <material name="silver"/>
  </visual>
  <collision>
    <origin xyz="-0.129269 -0.033452 0.3081" rpy="0 0 0"/>
    <geometry>
      <mesh filename="package://day_description/meshes/right_wheel_1.stl" scale="0.001 0.001 0.001"/>
    </geometry>
  </collision>
</link>

<joint name="Rev1" type="continuous">
  <origin xyz="0.126106 0.143452 -0.307951" rpy="0 0 0"/>
  <parent link="base_link"/>
  <child link="left_wheel_1"/>
  <axis xyz="-0.0 1.0 -0.0"/>
</joint>

<joint name="Rev2" type="continuous">
  <origin xyz="0.129269 0.033452 -0.3081" rpy="0 0 0"/>
  <parent link="base_link"/>
  <child link="right_wheel_1"/>
  <axis xyz="0.0 -1.0 0.0"/>
</joint>

</robot>
